Workbook
Name GeocodeAddressColumn_Map: Map!$G$1
Name GeocodeAddressColumn_QualityReport: 'Quality Report'!$B$1
Name GeocodeAddressColumn_Sheet12: #REF!

Sheet Reporte SDR General
C2: Day In | D2: Day Out
C3: 45870 | D3: 45901 | G3: =EOMONTH(C3,-4)+1 -> 45778 | H3: =EOMONTH(D3,-1) -> 45900
C4: =EOMONTH(C3,-2)+1 -> 45839 | D4: =EDATE(D3, -1) -> 45870
D5: TOTAL | E5: % | F5: Δ% vs PP | H5: Total | I5: % | J5: Δ% vs PP | K5: Manufacturers | L5: % | M5: Δ% vs PP | N5: Individuals | O5: % | P5: Δ% vs PP
C6: Total Leads SDR | D6: =H6 -> 0 | F6: =iferror(D6/'PT Reporte SDR'!D6-1,"") | H6: =COUNTIFS(Data!$A:$A,">="&'Reporte SDR General'!$C$3,Data!$A:$A,"<="&'Reporte SDR General'!$D$3) -> 0 | J6: =iferror(H6/'PT Reporte SDR'!H6-1,"") | K6: =COUNTIFS(Data!$A:$A,">="&'Reporte SDR General'!$C$3,Data!$A:$A,"<="&'Reporte SDR General'!$D$3,Data!$BI:$BI,K5) -> 0 | M6: =iferror(K6/'PT Reporte SDR'!K6-1,"") | N6: =COUNTIFS(Data!$A:$A,">="&'Reporte SDR General'!$C$3,Data!$A:$A,"<="&'Reporte SDR General'!$D$3,Data!$BI:$BI,N5) -> 0 | P6: =iferror(N6/'PT Reporte SDR'!N6-1,"")
C7: Prueba | D7: =Sum(H7+K7+N7) -> 0 | E7: =iferror(D7/$D$6,"0%") -> 0% | F7: =D7/D6 -> #DIV/0! | H7: =COUNTIFS(Data!$A:$A,">="&'Reporte SDR General'!$C$3,Data!$A:$A,"<="&'Reporte SDR General'!$D$3,Data!$X:$X,C7) -> 0 | I7: =iferror(H7/$D$43,0) -> 0 | J7: =iferror(H7/'PT Reporte SDR'!H65-1,"") | K7: =COUNTIFS(Data!$A:$A,">="&'Reporte SDR General'!$C$3,Data!$A:$A,"<="&'Reporte SDR General'!$D$3,Data!$BI:$BI,$H$5,Data!$CM:$CM,C7) -> 0 | L7: =iferror(K7/$D$43,0) -> 0 | M7: =iferror(K7/'PT Reporte SDR'!K65-1,"") | N7: =COUNTIFS(Data!$A:$A,">="&'Reporte SDR General'!$C$3,Data!$A:$A,"<="&'Reporte SDR General'!$D$3,Data!$BI:$BI,$H$5,Data!$CM:$CM,C7) -> 0 | O7: =iferror(N7/$D$43,0) -> 0 | P7: =iferror(N7/'PT Reporte SDR'!N65-1,"")
C8: Total Leads Incontactables por base de datos | D8: =H8 -> 0 | E8: =iferror(D8/$D$6,"0%") -> 0% | F8: =iferror(D8/'PT Reporte SDR'!D7-1,"") | H8: =H43 -> 0 | I8: =iferror(H8/$D$6,"0%") -> 0% | J8: =iferror(H8/'PT Reporte SDR'!H7-1,"") | K8: =K43 -> 0 | L8: =iferror(K8/$D$6,"0%") -> 0% | M8: =iferror(K8/'PT Reporte SDR'!K7-1,"") | N8: =N43 -> 0 | O8: =iferror(N8/$D$6,"0%") -> 0% | P8: =iferror(N8/'PT Reporte SDR'!N7-1,"")
C9: Total Leads Contactables | D9: =H9 -> 0 | E9: =iferror(D9/$D$6,"0%") -> 0% | F9: =iferror(D9/'PT Reporte SDR'!D8-1,"") | H9: =H6-H8 -> 0 | I9: =iferror(H9/$D$6,"0%") -> 0% | J9: =iferror(H9/'PT Reporte SDR'!H8-1,"") | K9: =K6-K8 -> 0 | L9: =iferror(K9/$D$6,"0%") -> 0% | M9: =iferror(K9/'PT Reporte SDR'!K8-1,"") | N9: =N6-N8 -> 0 | O9: =iferror(N9/$D$6,"0%") -> 0% | P9: =iferror(N9/'PT Reporte SDR'!N8-1,"")
C10: Total Leads Contactados (con al menos 1 Toque) | D10: =H10 -> 54 | E10: =iferror(D10/D9,"0%") -> 0% | F10: =iferror(D10/'PT Reporte SDR'!D9-1,"") | H10: =COUNTIFS(Data!$A:$A,">="&'Reporte SDR General'!$C$3,Data!$A:$A,"<="&'Reporte SDR General'!$D$3,Data!$Z:$Z,">0")+54 -> 54 | I10: =iferror(H10/H9,"0%") -> 0% | J10: =iferror(H10/'PT Reporte SDR'!H9-1,"") | K10: =COUNTIFS(Data!$A:$A,">="&'Reporte SDR General'!$C$3,Data!$A:$A,"<="&'Reporte SDR General'!$D$3,Data!$BI:$BI,K5,Data!$AT:$AT,"<>")-K8 -> 0 | L10: =iferror(K10/K9,"0%") -> 0% | M10: =iferror(K10/'PT Reporte SDR'!K9-1,"") | N10: =COUNTIFS(Data!$A:$A,">="&'Reporte SDR General'!$C$3,Data!$A:$A,"<="&'Reporte SDR General'!$D$3,Data!$BI:$BI,N5,Data!$AT:$AT,"<>")-N8 -> 0 | O10: =iferror(N10/N9,"0%") -> 0% | P10: =iferror(N10/'PT Reporte SDR'!N9-1,"")
C11: Total Lead en Proceso de Contacto (aún sin respuesta) | D11: =H11 -> 156 | E11: =iferror(D11/$D$6,"0%") -> 0% | F11: =iferror(D11/'PT Reporte SDR'!D10-1,"") -> 1.1971831 | H11: =156 -> 156 | I11: =iferror(H11/$D$6,"0%") -> 0% | J11: =iferror(H11/'PT Reporte SDR'!H10-1,"") -> 1.1971831 | K11: =COUNTIFS(Data!$A:$A,">="&'Reporte SDR General'!$C$3,Data!$A:$A,"<="&'Reporte SDR General'!$D$3,Data!$BI:$BI,K5,Data!$BK:$BK,"No respondio") -> 0 | L11: =iferror(K11/$D$6,"0%") -> 0% | M11: =iferror(K11/'PT Reporte SDR'!K10-1,"") | N11: =COUNTIFS(Data!$A:$A,">="&'Reporte SDR General'!$C$3,Data!$A:$A,"<="&'Reporte SDR General'!$D$3,Data!$BI:$BI,N5,Data!$BK:$BK,"No respondio") -> 0 | O11: =iferror(N11/$D$6,"0%") -> 0% | P11: =iferror(N11/'PT Reporte SDR'!N10-1,"")
C12: Total Leads Contactados sin Respuesta (6to Toque o más) | D12: =H12 -> 0 | E12: =iferror(IFERROR(D12/D10,0),"") -> 0 | F12: =iferror(D12/'PT Reporte SDR'!D11-1,"") | H12: =H73 -> 0 | I12: =iferror(IFERROR(H12/H10,0),"") -> 0 | J12: =iferror(H12/'PT Reporte SDR'!H11-1,"") | K12: =COUNTIFS(Data!$A:$A,">="&'Reporte SDR General'!$C$3,Data!$A:$A,"<="&'Reporte SDR General'!$D$3,Data!$BI:$BI,K5,Data!$AT:$AT,">=6") -> 0 | L12: =iferror(IFERROR(K12/K10,0),"") -> 0 | M12: =iferror(K12/'PT Reporte SDR'!K11-1,"") | N12: =COUNTIFS(Data!$A:$A,">="&'Reporte SDR General'!$C$3,Data!$A:$A,"<="&'Reporte SDR General'!$D$3,Data!$BI:$BI,N5,Data!$AT:$AT,">=6") -> 0 | O12: =iferror(IFERROR(N12/N10,0),"") -> 0 | P12: =iferror(N12/'PT Reporte SDR'!N11-1,"")
C13: Total Leads Contactados con Respuesta | D13: =H13 -> 1 | E13: =iferror(D13/D9,"0%") -> 0% | F13: =iferror(D13/'PT Reporte SDR'!D12-1,"") | H13: =H49+1 -> 1 | I13: =iferror(H13/H9,"0%") -> 0% | J13: =iferror(H13/'PT Reporte SDR'!H12-1,"") | K13: =COUNTIFS(Data!$A:$A,">="&'Reporte SDR General'!$C$3,Data!$A:$A,"<="&'Reporte SDR General'!$D$3,Data!$BI:$BI,K5,Data!$BK:$BK,"Pase a ventas")+COUNTIFS(Data!$A:$A,">="&'Reporte SDR General'!$C$3,Data!$A:$A,"<="&'Reporte SDR General'!$D$3,Data!$BI:$BI,K5,Data!$BK:$BK,"Descartado")+COUNTIFS(Data!$A:$A,">="&'Reporte SDR General'!$C$3,Data!$A:$A,"<="&'Reporte SDR General'!$D$3,Data!$BI:$BI,K5,Data!$BK:$BK,"Pidio llamar mas tarde")+COUNTIFS(Data!$A:$A,">="&'Reporte SDR General'!$C$3,Data!$A:$A,"<="&'Reporte SDR General'!$D$3,Data!$BI:$BI,K5,Data!$BK:$BK,"Contesta y Cuelga")+COUNTIFS(Data!$A:$A,">="&'Reporte SDR General'!$C$3,Data!$A:$A,"<="&'Reporte SDR General'!$D$3,Data!$BI:$BI,K5,Data!$BK:$BK,"Llamar mañana")+COUNTIFS(Data!$A:$A,">="&'Reporte SDR General'!$C$3,Data!$A:$A,"<="&'Reporte SDR General'!$D$3,Data!$BI:$BI,K5,Data!$BK:$BK,"SEGUIMIENTO") -> 0 | L13: =iferror(K13/K9,"0%") -> 0% | M13: =iferror(K13/'PT Reporte SDR'!K12-1,"") | N13: =COUNTIFS(Data!$A:$A,">="&'Reporte SDR General'!$C$3,Data!$A:$A,"<="&'Reporte SDR General'!$D$3,Data!$BI:$BI,N5,Data!$BK:$BK,"Pase a ventas")+COUNTIFS(Data!$A:$A,">="&'Reporte SDR General'!$C$3,Data!$A:$A,"<="&'Reporte SDR General'!$D$3,Data!$BI:$BI,N5,Data!$BK:$BK,"Descartado")+COUNTIFS(Data!$A:$A,">="&'Reporte SDR General'!$C$3,Data!$A:$A,"<="&'Reporte SDR General'!$D$3,Data!$BI:$BI,N5,Data!$BK:$BK,"Pidio llamar mas tarde")+COUNTIFS(Data!$A:$A,">="&'Reporte SDR General'!$C$3,Data!$A:$A,"<="&'Reporte SDR General'!$D$3,Data!$BI:$BI,N5,Data!$BK:$BK,"Contesta y Cuelga")+COUNTIFS(Data!$A:$A,">="&'Reporte SDR General'!$C$3,Data!$A:$A,"<="&'Reporte SDR General'!$D$3,Data!$BI:$BI,N5,Data!$BK:$BK,"Llamar mañana")+COUNTIFS(Data!$A:$A,">="&'Reporte SDR General'!$C$3,Data!$A:$A,"<="&'Reporte SDR General'!$D$3,Data!$BI:$BI,N5,Data!$BK:$BK,"SEGUIMIENTO") -> 0 | O13: =iferror(N13/N9,"0%") -> 0% | P13: =iferror(N13/'PT Reporte SDR'!N12-1,"")
C14: Total Leads Con Dialogo Completo | D14: =H14 -> 0 | E14: =IFERROR(D14/$D$13,0) -> 0 | F14: =iferror(D14/'PT Reporte SDR'!D13-1,"") | H14: =COUNTIFS(Data!$A:$A,">="&'Reporte SDR General'!$C$3,Data!$A:$A,"<="&'Reporte SDR General'!$D$3,Data!$AB:$AB,"Diálogo Completo") -> 0 | I14: =IFERROR(H14/$D$13,0) -> 0 | J14: =iferror(H14/'PT Reporte SDR'!H13-1,"") | K14: =COUNTIFS(Data!$A:$A,">="&'Reporte SDR General'!$C$3,Data!$A:$A,"<="&'Reporte SDR General'!$D$3,Data!$BI:$BI,K5,Data!$W:$W,"Diálogo Completo") -> 0 | L14: =IFERROR(K14/$D$13,0) -> 0 | M14: =iferror(K14/'PT Reporte SDR'!K13-1,"") | N14: =COUNTIFS(Data!$A:$A,">="&'Reporte SDR General'!$C$3,Data!$A:$A,"<="&'Reporte SDR General'!$D$3,Data!$BI:$BI,N5,Data!$W:$W,"Diálogo Completo") -> 0 | O14: =IFERROR(N14/$D$13,0) -> 0 | P14: =iferror(N14/'PT Reporte SDR'!N13-1,"")
C15: Total Leads Intermitentes | D15: =H15 -> 6 | E15: =IFERROR(D15/$D$13,0) -> 6 | F15: =iferror(D15/'PT Reporte SDR'!D14-1,"") -> 5 | H15: =COUNTIFS(Data!$A:$A,">="&'Reporte SDR General'!$C$3,Data!$A:$A,"<="&'Reporte SDR General'!$D$3,Data!$AB:$AB,"Intermitente")+6 -> 6 | I15: =IFERROR(H15/$D$13,0) -> 6 | J15: =iferror(H15/'PT Reporte SDR'!H14-1,"") -> 5 | K15: =COUNTIFS(Data!$A:$A,">="&'Reporte SDR General'!$C$3,Data!$A:$A,"<="&'Reporte SDR General'!$D$3,Data!$BI:$BI,K5,Data!$W:$W,"Intermitente") -> 0 | L15: =IFERROR(K15/$D$13,0) -> 0 | M15: =iferror(K15/'PT Reporte SDR'!K14-1,"") | N15: =COUNTIFS(Data!$A:$A,">="&'Reporte SDR General'!$C$3,Data!$A:$A,"<="&'Reporte SDR General'!$D$3,Data!$BI:$BI,N5,Data!$W:$W,"Intermitente") -> 0 | O15: =IFERROR(N15/$D$13,0) -> 0 | P15: =iferror(N15/'PT Reporte SDR'!N14-1,"")
C16: Leads que entendieron comunicación | D16: =H16 -> 8 | E16: =IFERROR(D16/$D$13,0) -> 8 | F16: =iferror(D16/'PT Reporte SDR'!D15-1,"") | H16: =COUNTIFS(Data!$A:$A,">="&'Reporte SDR General'!$C$3,Data!$A:$A,"<="&'Reporte SDR General'!$D$3,Data!$AF:$AF,"Si")+8 -> 8 | I16: =IFERROR(H16/$D$13,0) -> 8 | J16: =iferror(H16/'PT Reporte SDR'!H15-1,"") | K16: =COUNTIFS(Data!$A:$A,">="&'Reporte SDR General'!$C$3,Data!$A:$A,"<="&'Reporte SDR General'!$D$3,Data!$BI:$BI,K5,Data!$AJ:$AJ,"Si") -> 0 | L16: =IFERROR(K16/$D$13,0) -> 0 | M16: =iferror(K16/'PT Reporte SDR'!K15-1,"") | N16: =COUNTIFS(Data!$A:$A,">="&'Reporte SDR General'!$C$3,Data!$A:$A,"<="&'Reporte SDR General'!$D$3,Data!$BI:$BI,N5,Data!$AJ:$AJ,"Si") -> 0 | O16: =IFERROR(N16/$D$13,0) -> 0 | P16: =iferror(N16/'PT Reporte SDR'!N15-1,"")
C17: Leads que no entendieron comunicación | D17: =H17 -> 0 | E17: =IFERROR(D17/$D$13,0) -> 0 | F17: =iferror(D17/'PT Reporte SDR'!D16-1,"") | H17: =COUNTIFS(Data!$A:$A,">="&'Reporte SDR General'!$C$3,Data!$A:$A,"<="&'Reporte SDR General'!$D$3,Data!$AF:$AF,"No") -> 0 | I17: =IFERROR(H17/$D$13,0) -> 0 | J17: =iferror(H17/'PT Reporte SDR'!H16-1,"") | K17: =COUNTIFS(Data!$A:$A,">="&'Reporte SDR General'!$C$3,Data!$A:$A,"<="&'Reporte SDR General'!$D$3,Data!$BI:$BI,K5,Data!$AJ:$AJ,"No") -> 0 | L17: =IFERROR(K17/$D$13,0) -> 0 | M17: =iferror(K17/'PT Reporte SDR'!K16-1,"") | N17: =COUNTIFS(Data!$A:$A,">="&'Reporte SDR General'!$C$3,Data!$A:$A,"<="&'Reporte SDR General'!$D$3,Data!$BI:$BI,N5,Data!$AJ:$AJ,"No") -> 0 | O17: =IFERROR(N17/$D$13,0) -> 0 | P17: =iferror(N17/'PT Reporte SDR'!N16-1,"")
C18: Leads que mostraron interés | D18: =H18 -> 4 | E18: =IFERROR(D18/$D$13,0) -> 4 | F18: =iferror(D18/'PT Reporte SDR'!D17-1,"") -> 0.33333333 | H18: =COUNTIFS(Data!$A:$A,">="&'Reporte SDR General'!$C$3,Data!$A:$A,"<="&'Reporte SDR General'!$D$3,Data!$AG:$AG,"Si")+4 -> 4 | I18: =IFERROR(H18/$D$13,0) -> 4 | J18: =iferror(H18/'PT Reporte SDR'!H17-1,"") -> 0.33333333 | K18: =COUNTIFS(Data!$A:$A,">="&'Reporte SDR General'!$C$3,Data!$A:$A,"<="&'Reporte SDR General'!$D$3,Data!$BI:$BI,K5,Data!$BK:$BK,"Pase a ventas") -> 0 | L18: =IFERROR(K18/$D$13,0) -> 0 | M18: =iferror(K18/'PT Reporte SDR'!K17-1,"") | N18: =COUNTIFS(Data!$A:$A,">="&'Reporte SDR General'!$C$3,Data!$A:$A,"<="&'Reporte SDR General'!$D$3,Data!$BI:$BI,N5,Data!$BK:$BK,"Pase a ventas") -> 0 | O18: =IFERROR(N18/$D$13,0) -> 0 | P18: =iferror(N18/'PT Reporte SDR'!N17-1,"")
C19: Total Leads Descartados | D19: =H19 -> 16 | E19: =iferror(D19/D6,"0%") -> 0% | F19: =iferror(D19/'PT Reporte SDR'!D18-1,"") | H19: =H20+H21 -> 16 | I19: =iferror(H19/H6,"0%") -> 0% | J19: =iferror(H19/'PT Reporte SDR'!H18-1,"") | K19: =K20+K21 -> 0 | L19: =iferror(K19/K6,"0%") -> 0% | M19: =iferror(K19/'PT Reporte SDR'!K18-1,"") | N19: =N20+N21 -> 0 | O19: =iferror(N19/N6,"0%") -> 0% | P19: =iferror(N19/'PT Reporte SDR'!N18-1,"")
C20: Leads que no mostraron interés | D20: =H20 -> 0 | E20: =IFERROR(D20/$D$13,0) -> 0 | F20: =iferror(D20/'PT Reporte SDR'!D19-1,"") | H20: =COUNTIFS(Data!$A:$A,">="&'Reporte SDR General'!$C$3,Data!$A:$A,"<="&'Reporte SDR General'!$D$3,Data!$AG:$AG,"No") -> 0 | I20: =IFERROR(H20/$D$13,0) -> 0 | J20: =iferror(H20/'PT Reporte SDR'!H19-1,"") | K20: =COUNTIFS(Data!$A:$A,">="&'Reporte SDR General'!$C$3,Data!$A:$A,"<="&'Reporte SDR General'!$D$3,Data!$BI:$BI,K5,Data!$AJ:$AJ,"No") -> 0 | L20: =IFERROR(K20/$D$13,0) -> 0 | M20: =iferror(K20/'PT Reporte SDR'!K19-1,"") | N20: =COUNTIFS(Data!$A:$A,">="&'Reporte SDR General'!$C$3,Data!$A:$A,"<="&'Reporte SDR General'!$D$3,Data!$BI:$BI,N5,Data!$AJ:$AJ,"No") -> 0 | O20: =IFERROR(N20/$D$13,0) -> 0 | P20: =iferror(N20/'PT Reporte SDR'!N19-1,"")
C21: Otras razones | D21: =H21 -> 16 | E21: =IFERROR(D21/$D$13,0) -> 16 | F21: =iferror(D21/'PT Reporte SDR'!D20-1,"") | H21: =H76+D76-1 -> 16 | I21: =IFERROR(H21/$D$13,0) -> 16 | J21: =iferror(H21/'PT Reporte SDR'!H20-1,"") | K21: =K76 -> 0 | L21: =IFERROR(K21/$D$13,0) -> 0 | M21: =iferror(K21/'PT Reporte SDR'!K20-1,"") | N21: =N76 -> 0 | O21: =IFERROR(N21/$D$13,0) -> 0 | P21: =iferror(N21/'PT Reporte SDR'!N20-1,"")
C22: Total Leads en seguimiento para venta | D22: =H22 -> 0 | E22: =IFERROR(D22/$D$13,0) -> 0 | F22: =iferror(D22/'PT Reporte SDR'!D21-1,"") | H22: =COUNTIFS(Data!$A:$A,">="&'Reporte SDR General'!$C$3,Data!$A:$A,"<="&'Reporte SDR General'!$D$3,Data!$W:$W,"En Seguimiento") -> 0 | I22: =IFERROR(H22/$D$13,0) -> 0 | J22: =iferror(H22/'PT Reporte SDR'!H21-1,"") | K22: =COUNTIFS(Data!$A:$A,">="&'Reporte SDR General'!$C$3,Data!$A:$A,"<="&'Reporte SDR General'!$D$3,Data!$BI:$BI,K5,Data!$BK:$BK,"SEGUIMIENTO") -> 0 | L22: =IFERROR(K22/$D$13,0) -> 0 | M22: =iferror(K22/'PT Reporte SDR'!K21-1,"") | N22: =COUNTIFS(Data!$A:$A,">="&'Reporte SDR General'!$C$3,Data!$A:$A,"<="&'Reporte SDR General'!$D$3,Data!$BI:$BI,N5,Data!$BK:$BK,"SEGUIMIENTO") -> 0 | O22: =IFERROR(N22/$D$13,0) -> 0 | P22: =iferror(N22/'PT Reporte SDR'!N21-1,"")
C23: Total Leads Asignados a Ventas | D23: =H23 -> 0 | E23: =iferror(D23/D18,"0%") -> 0 | F23: =iferror(D23/'PT Reporte SDR'!D22-1,"") | H23: =H24+H25 -> 0
C24: Leads Asignados a Ventas Periodo Actual | D24: =H24 -> 0 | E24: =IFERROR(D24/D18,0) -> 0 | F24: =iferror(D24/'PT Reporte SDR Brazil'!D23-1,"") -> -1 | H24: =COUNTIFS(Data!A:A,">="&'Reporte SDR General'!$C$3,Data!A:A,"<="&'Reporte SDR General'!$D$3,Data!$W:$W,"Paso a ventas") -> 0
C25: Leads Asignados a Ventas Carry-Over | D25: =H25 -> 0 | E25: =IFERROR(D25/#REF!,0) -> 0 | F25: =iferror(D25/'PT Reporte SDR Brazil'!D24-1,"") | H25: =COUNTIFS(Data!A:A,">="&'Reporte SDR General'!$C$4,Data!A:A,"<="&'Reporte SDR General'!$D$4,Data!$W:$W,"Paso a ventas",Data!BY:BY,">="&'Reporte SDR General'!$C$3,Data!BY:BY,"<="&'Reporte SDR General'!$D$3) -> 0
C26: Leads Asignados a Ventas Periodo Anterior (Histórico) | D26: =H26 -> 0 | E26: =D26/D23 -> #DIV/0! | F26: =iferror(D26/'PT Reporte SDR Brazil'!D25-1,"") | H26: =COUNTIFS(Data!A:A,">="&'Reporte SDR General'!$G$3,Data!A:A,"<="&'Reporte SDR General'!$H$3,Data!$W:$W,"Paso a ventas") -> 0
C27: Monto de Inversión asignada a Ventas (leads este mes) | D27: =H27 -> #N/A | E27: =IFERROR(D27/D23,0) -> 0 | F27: =iferror(D27/'PT Reporte SDR Brazil'!D26-1,"") | H27: =SUMIFS(Data!BQ:BQ,Data!A:A,">="&'Reporte SDR General'!$C$3,Data!A:A,"<="&'Reporte SDR General'!$D$3,Data!$W:$W,"Paso a ventas") -> #N/A
C28: Monto de Inversión asignada a Ventas Carry-Over (Leads Mes anterior) | D28: =H28 -> #N/A | E28: =iferror(D28/$D$71,0) -> 0 | F28: =iferror(D28/'PT Reporte SDR Brazil'!D27-1,"") | H28: =SUMIFS(Data!BQ:BQ,Data!A:A,">="&'Reporte SDR General'!$C$4,Data!A:A,"<="&'Reporte SDR General'!$D$4,Data!$W:$W,"Paso a ventas") -> #N/A
C29: Monto de inversión asignada a ventas total mes | D29: =H29 -> #N/A | E29: $ | F29: =iferror(D29/'PT Reporte SDR Brazil'!D28-1,"") | H29: =SUMIFS(Data!BQ:BQ,Data!A:A,">="&'Reporte SDR General'!$G$3,Data!A:A,"<="&'Reporte SDR General'!$H$3,Data!$W:$W,"Paso a ventas") -> #N/A | J29: =iferror(H29/'PT Reporte SDR Brazil'!H28-1,"")
C30: Monto de Inversión asignada a Ventas Total todos los tiempos | D30: =H30 -> 11605 | E30: =IFERROR(D30/D27,0) -> 0 | F30: =iferror(D30/'PT Reporte SDR Brazil'!D29-1,"") | H30: 11605 | I30: =IFERROR(H30/H27,0) -> 0 | J30: =iferror(H30/'PT Reporte SDR Brazil'!H29-1,"")
C31: Monto de Inversión asignada a Ventas Historico aún en seguimiento (sin mes anterior) | D31: =H31 | F31: =iferror(D31/'PT Reporte SDR Brazil'!D30-1,"") | J31: =iferror(H31/'PT Reporte SDR Brazil'!H30-1,"")
C32: Monto de inversión asignado a ventas Total General en seguimiento | D32: =H32 | F32: =iferror(D32/'PT Reporte SDR Brazil'!D31-1,"") | J32: =iferror(H32/'PT Reporte SDR Brazil'!H31-1,"")
C33: Monto de inversión Perdida | D33: =H33 | E33: =IFERROR(D33/D27,0) -> 0 | F33: =iferror(D33/'PT Reporte SDR Brazil'!D32-1,"") | I33: =IFERROR(H33/H27,0) -> 0 | J33: =iferror(H33/'PT Reporte SDR Brazil'!H32-1,"")
C34: Monto de Inversión Promedio por Prospecto | D34: =D30/D23 -> #DIV/0! | E34: =IFERROR(D34/D27,0) -> 0 | F34: =iferror(D34/'PT Reporte SDR Brazil'!D33-1,"") | H34: =D34 -> #DIV/0! | I34: =IFERROR(H34/H27,0) -> 0 | J34: =iferror(H34/'PT Reporte SDR Brazil'!H33-1,"")
C35: Monto de Inversión Promedio por Prospecto Periodo Anterior | D35: =H35 | F35: =iferror(D35/'PT Reporte SDR Brazil'!D34-1,"") | J35: =iferror(H35/'PT Reporte SDR Brazil'!H34-1,"")
C36: Deals Cerrados Pagados | D36: =H36 -> 8 | F36: =iferror(D36/'PT Reporte SDR Brazil'!D35-1,"") | H36: 8 | J36: =iferror(H36/'PT Reporte SDR Brazil'!H35-1,"")
C37: Monto de cierres | D37: =H37 -> 3240 | F37: =iferror(D37/'PT Reporte SDR Brazil'!D36-1,"") | H37: 3240 | J37: =iferror(H37/'PT Reporte SDR Brazil'!H36-1,"")
F38: =iferror(D38/'PT Reporte SDR'!D60-1,"") | J38: =iferror(H38/'PT Reporte SDR'!H60-1,"") | M38: =iferror(K38/'PT Reporte SDR'!K60-1,"") | P38: =iferror(N38/'PT Reporte SDR'!N60-1,"")
C39: Total Leads Incontactables | D39: Total | E39: % | F39: =iferror(D39/'PT Reporte SDR'!D61-1,"") | I39: % | J39: =iferror(H39/'PT Reporte SDR'!H61-1,"") | L39: % | M39: =iferror(K39/'PT Reporte SDR'!K61-1,"") | O39: % | P39: =iferror(N39/'PT Reporte SDR'!N61-1,"")
A40: {=UNIQUE(Data!BJ:BJ)} -> #REF! | C40: Duplicado | D40: =Sum(H40+K40+N40) -> 0 | E40: =iferror(D40/$D$43,0) -> 0 | F40: =iferror(D40/'PT Reporte SDR'!D62-1,"") | H40: =COUNTIFS(Data!$A:$A,">="&'Reporte SDR General'!$C$3,Data!$A:$A,"<="&'Reporte SDR General'!$D$3,Data!$X:$X,C40) -> 0 | I40: =iferror(H40/$D$43,0) -> 0 | J40: =iferror(H40/'PT Reporte SDR'!H62-1,"") | K40: =COUNTIFS(Data!$A:$A,">="&'Reporte SDR General'!$C$3,Data!$A:$A,"<="&'Reporte SDR General'!$D$3,Data!$BI:$BI,$H$5,Data!$CM:$CM,C40) -> 0 | L40: =iferror(K40/$D$43,0) -> 0 | M40: =iferror(K40/'PT Reporte SDR'!K62-1,"") | N40: =COUNTIFS(Data!$A:$A,">="&'Reporte SDR General'!$C$3,Data!$A:$A,"<="&'Reporte SDR General'!$D$3,Data!$BI:$BI,$H$5,Data!$CM:$CM,C40) -> 0 | O40: =iferror(N40/$D$43,0) -> 0 | P40: =iferror(N40/'PT Reporte SDR'!N62-1,"")
C41: Equivocado | D41: =Sum(H41+K41+N41) -> 0 | E41: =iferror(D41/$D$43,0) -> 0 | F41: =iferror(D41/'PT Reporte SDR'!D63-1,"") | H41: =COUNTIFS(Data!$A:$A,">="&'Reporte SDR General'!$C$3,Data!$A:$A,"<="&'Reporte SDR General'!$D$3,Data!$X:$X,C41) -> 0 | I41: =iferror(H41/$D$43,0) -> 0 | J41: =iferror(H41/'PT Reporte SDR'!H63-1,"") | K41: =COUNTIFS(Data!$A:$A,">="&'Reporte SDR General'!$C$3,Data!$A:$A,"<="&'Reporte SDR General'!$D$3,Data!$BI:$BI,$H$5,Data!$CM:$CM,C41) -> 0 | L41: =iferror(K41/$D$43,0) -> 0 | M41: =iferror(K41/'PT Reporte SDR'!K63-1,"") | N41: =COUNTIFS(Data!$A:$A,">="&'Reporte SDR General'!$C$3,Data!$A:$A,"<="&'Reporte SDR General'!$D$3,Data!$BI:$BI,$H$5,Data!$CM:$CM,C41) -> 0 | O41: =iferror(N41/$D$43,0) -> 0 | P41: =iferror(N41/'PT Reporte SDR'!N63-1,"")
...

Sheet PT Reporte SDR
C2: Day In | D2: Day Out
C3: =EOMONTH('Reporte SDR General'!C3,-2)+92 -> 45930 | D3: =EDATE('Reporte SDR General'!D3, -1)+1 -> 45871
C4: =EOMONTH(C3,-2)+1 -> 45870 | D4: =EDATE(D3, -1) -> 45840
D5: TOTAL | E5: % | F5: Δ% vs PP | H5: Total | I5: Manufacturers | J5: Individuals
C6: Total Leads SDR | D6: =H6 -> 0 | F6: =iferror(D6/'Periodo Anterior'!D6-1,"") | H6: =COUNTIFS(Data!$A:$A,">="&'PT Reporte SDR'!$C$3,Data!$A:$A,"<="&'PT Reporte SDR'!$D$3) -> 0 | I6: =COUNTIFS(Data!$A:$A,">="&'PT Reporte SDR'!$C$3,Data!$A:$A,"<="&'PT Reporte SDR'!$D$3,Data!$BI:$BI,I5) -> 0 | J6: =COUNTIFS(Data!$A:$A,">="&'PT Reporte SDR'!$C$3,Data!$A:$A,"<="&'PT Reporte SDR'!$D$3,Data!$BI:$BI,J5) -> 0
C7: Total Leads Incontactables por base de datos | D7: =H7 -> 0 | E7: =iferror(D7/$D$6,"0%") -> 0% | F7: =iferror(D7/'Periodo Anterior'!D7-1,"") | H7: =H66 -> 0 | I7: =I66 -> 0 | J7: =J66 -> 0
C8: Total Leads Contactables | D8: =H8 -> 0 | E8: =iferror(D8/$D$6,"0%") -> 0% | F8: =iferror(D8/'Periodo Anterior'!D8-1,"") | H8: =H6-H7 -> 0 | I8: =I6-I7 -> 0 | J8: =J6-J7 -> 0
C9: Total Leads Contactados (con al menos 1 Toque) | D9: =H9 -> 0 | E9: =iferror(D9/D8,"0%") -> 0% | F9: =iferror(D9/'Periodo Anterior'!D9-1,"") | H9: =COUNTIFS(Data!$A:$A,">="&'PT Reporte SDR'!$C$3,Data!$A:$A,"<="&'PT Reporte SDR'!$D$3,Data!$Z:$Z,">0") -> 0 | I9: =COUNTIFS(Data!$A:$A,">="&'PT Reporte SDR'!$C$3,Data!$A:$A,"<="&'PT Reporte SDR'!$D$3,Data!$BI:$BI,I5,Data!$AT:$AT,"<>")-I7 -> 0 | J9: =COUNTIFS(Data!$A:$A,">="&'PT Reporte SDR'!$C$3,Data!$A:$A,"<="&'PT Reporte SDR'!$D$3,Data!$BI:$BI,J5,Data!$AT:$AT,"<>")-J7 -> 0
C10: Total Lead en Proceso de Contacto (aún sin respuesta) | D10: =H10 -> 71 | E10: =iferror(D10/$D$6,"0%") -> 0% | F10: =iferror(D10/'Periodo Anterior'!D10-1,"") | H10: 71 | I10: =COUNTIFS(Data!$A:$A,">="&'PT Reporte SDR'!$C$3,Data!$A:$A,"<="&'PT Reporte SDR'!$D$3,Data!$BI:$BI,I5,Data!$BK:$BK,"No respondio") -> 0 | J10: =COUNTIFS(Data!$A:$A,">="&'PT Reporte SDR'!$C$3,Data!$A:$A,"<="&'PT Reporte SDR'!$D$3,Data!$BI:$BI,J5,Data!$BK:$BK,"No respondio") -> 0
C11: Total Leads Contactados sin Respuesta (6to Toque o más) | D11: =H11 -> 0 | E11: =iferror(IFERROR(D11/D9,0),"") -> 0 | F11: =iferror(D11/'Periodo Anterior'!D11-1,"") | H11: =H96 -> 0 | I11: =COUNTIFS(Data!$A:$A,">="&'PT Reporte SDR'!$C$3,Data!$A:$A,"<="&'PT Reporte SDR'!$D$3,Data!$BI:$BI,I5,Data!$AT:$AT,">=6") -> 0 | J11: =COUNTIFS(Data!$A:$A,">="&'PT Reporte SDR'!$C$3,Data!$A:$A,"<="&'PT Reporte SDR'!$D$3,Data!$BI:$BI,J5,Data!$AT:$AT,">=6") -> 0
C12: Total Leads Contactados con Respuesta | D12: =H12 -> 0 | E12: =iferror(D12/D8,"0%") -> 0% | F12: =iferror(D12/'Periodo Anterior'!D12-1,"") | H12: =H72 -> 0 | I12: =COUNTIFS(Data!$A:$A,">="&'PT Reporte SDR'!$C$3,Data!$A:$A,"<="&'PT Reporte SDR'!$D$3,Data!$BI:$BI,I5,Data!$BK:$BK,"Pase a ventas")+COUNTIFS(Data!$A:$A,">="&'PT Reporte SDR'!$C$3,Data!$A:$A,"<="&'PT Reporte SDR'!$D$3,Data!$BI:$BI,I5,Data!$BK:$BK,"Descartado")+COUNTIFS(Data!$A:$A,">="&'PT Reporte SDR'!$C$3,Data!$A:$A,"<="&'PT Reporte SDR'!$D$3,Data!$BI:$BI,I5,Data!$BK:$BK,"Pidio llamar mas tarde")+COUNTIFS(Data!$A:$A,">="&'PT Reporte SDR'!$C$3,Data!$A:$A,"<="&'PT Reporte SDR'!$D$3,Data!$BI:$BI,I5,Data!$BK:$BK,"Contesta y Cuelga")+COUNTIFS(Data!$A:$A,">="&'PT Reporte SDR'!$C$3,Data!$A:$A,"<="&'PT Reporte SDR'!$D$3,Data!$BI:$BI,I5,Data!$BK:$BK,"Llamar mañana")+COUNTIFS(Data!$A:$A,">="&'PT Reporte SDR'!$C$3,Data!$A:$A,"<="&'PT Reporte SDR'!$D$3,Data!$BI:$BI,I5,Data!$BK:$BK,"SEGUIMIENTO") -> 0 | J12: =COUNTIFS(Data!$A:$A,">="&'PT Reporte SDR'!$C$3,Data!$A:$A,"<="&'PT Reporte SDR'!$D$3,Data!$BI:$BI,J5,Data!$BK:$BK,"Pase a ventas")+COUNTIFS(Data!$A:$A,">="&'PT Reporte SDR'!$C$3,Data!$A:$A,"<="&'PT Reporte SDR'!$D$3,Data!$BI:$BI,J5,Data!$BK:$BK,"Descartado")+COUNTIFS(Data!$A:$A,">="&'PT Reporte SDR'!$C$3,Data!$A:$A,"<="&'PT Reporte SDR'!$D$3,Data!$BI:$BI,J5,Data!$BK:$BK,"Pidio llamar mas tarde")+COUNTIFS(Data!$A:$A,">="&'PT Reporte SDR'!$C$3,Data!$A:$A,"<="&'PT Reporte SDR'!$D$3,Data!$BI:$BI,J5,Data!$BK:$BK,"Contesta y Cuelga")+COUNTIFS(Data!$A:$A,">="&'PT Reporte SDR'!$C$3,Data!$A:$A,"<="&'PT Reporte SDR'!$D$3,Data!$BI:$BI,J5,Data!$BK:$BK,"Llamar mañana")+COUNTIFS(Data!$A:$A,">="&'PT Reporte SDR'!$C$3,Data!$A:$A,"<="&'PT Reporte SDR'!$D$3,Data!$BI:$BI,J5,Data!$BK:$BK,"SEGUIMIENTO") -> 0
C13: Total Leads Con Dialogo Completo | D13: =H13 -> 0 | E13: =IFERROR(D13/$D$12,0) -> 0 | F13: =iferror(D13/'Periodo Anterior'!D13-1,"") | H13: =COUNTIFS(Data!$A:$A,">="&'PT Reporte SDR'!$C$3,Data!$A:$A,"<="&'PT Reporte SDR'!$D$3,Data!$AB:$AB,"Diálogo Completo") -> 0 | I13: =COUNTIFS(Data!$A:$A,">="&'PT Reporte SDR'!$C$3,Data!$A:$A,"<="&'PT Reporte SDR'!$D$3,Data!$BI:$BI,I5,Data!$W:$W,"Diálogo Completo") -> 0 | J13: =COUNTIFS(Data!$A:$A,">="&'PT Reporte SDR'!$C$3,Data!$A:$A,"<="&'PT Reporte SDR'!$D$3,Data!$BI:$BI,J5,Data!$W:$W,"Diálogo Completo") -> 0
C14: Total Leads Intermitentes | D14: =H14 -> 1 | E14: =IFERROR(D14/$D$12,0) -> 0 | F14: =iferror(D14/'Periodo Anterior'!D14-1,"") | H14: =COUNTIFS(Data!$A:$A,">="&'PT Reporte SDR'!$C$3,Data!$A:$A,"<="&'PT Reporte SDR'!$D$3,Data!$AB:$AB,"Intermitente")+1 -> 1 | I14: =COUNTIFS(Data!$A:$A,">="&'PT Reporte SDR'!$C$3,Data!$A:$A,"<="&'PT Reporte SDR'!$D$3,Data!$BI:$BI,I5,Data!$W:$W,"Intermitente") -> 0 | J14: =COUNTIFS(Data!$A:$A,">="&'PT Reporte SDR'!$C$3,Data!$A:$A,"<="&'PT Reporte SDR'!$D$3,Data!$BI:$BI,J5,Data!$W:$W,"Intermitente") -> 0
C15: Leads que entendieron comunicación | D15: =H15 -> 0 | E15: =IFERROR(D15/$D$12,0) -> 0 | F15: =iferror(D15/'Periodo Anterior'!D15-1,"") | H15: =COUNTIFS(Data!$A:$A,">="&'PT Reporte SDR'!$C$3,Data!$A:$A,"<="&'PT Reporte SDR'!$D$3,Data!$AF:$AF,"Si") -> 0 | I15: =COUNTIFS(Data!$A:$A,">="&'PT Reporte SDR'!$C$3,Data!$A:$A,"<="&'PT Reporte SDR'!$D$3,Data!$BI:$BI,I5,Data!$AJ:$AJ,"Si") -> 0 | J15: =COUNTIFS(Data!$A:$A,">="&'PT Reporte SDR'!$C$3,Data!$A:$A,"<="&'PT Reporte SDR'!$D$3,Data!$BI:$BI,J5,Data!$AJ:$AJ,"Si") -> 0
C16: Leads que no entendieron comunicación | D16: =H16 -> 0 | E16: =IFERROR(D16/$D$12,0) -> 0 | F16: =iferror(D16/'Periodo Anterior'!D21-1,"") | H16: =COUNTIFS(Data!$A:$A,">="&'PT Reporte SDR'!$C$3,Data!$A:$A,"<="&'PT Reporte SDR'!$D$3,Data!$AF:$AF,"No") -> 0 | I16: =COUNTIFS(Data!$A:$A,">="&'PT Reporte SDR'!$C$3,Data!$A:$A,"<="&'PT Reporte SDR'!$D$3,Data!$BI:$BI,I5,Data!$AJ:$AJ,"No") -> 0 | J16: =COUNTIFS(Data!$A:$A,">="&'PT Reporte SDR'!$C$3,Data!$A:$A,"<="&'PT Reporte SDR'!$D$3,Data!$BI:$BI,J5,Data!$AJ:$AJ,"No") -> 0
C17: Leads que mostraron interés | D17: =H17 -> 3 | E17: =IFERROR(D17/$D$12,0) -> 0 | F17: =iferror(D17/'Periodo Anterior'!D17-1,"") | H17: =COUNTIFS(Data!$A:$A,">="&'PT Reporte SDR'!$C$3,Data!$A:$A,"<="&'PT Reporte SDR'!$D$3,Data!$AG:$AG,"Si")+3 -> 3 | I17: =COUNTIFS(Data!$A:$A,">="&'PT Reporte SDR'!$C$3,Data!$A:$A,"<="&'PT Reporte SDR'!$D$3,Data!$BI:$BI,I5,Data!$BK:$BK,"Pase a ventas") -> 0 | J17: =COUNTIFS(Data!$A:$A,">="&'PT Reporte SDR'!$C$3,Data!$A:$A,"<="&'PT Reporte SDR'!$D$3,Data!$BI:$BI,J5,Data!$BK:$BK,"Pase a ventas") -> 0
C18: Total Leads Descartados | D18: =H18 -> 0 | E18: =iferror(D18/D6,"0%") -> 0% | F18: =iferror(D18/'Periodo Anterior'!D18-1,"") | H18: =H19+H20 -> 0 | I18: =I19+I20 -> 0 | J18: =J19+J20 -> 0
C19: Leads que no mostraron interés | D19: =H19 -> 0 | E19: =IFERROR(D19/$D$12,0) -> 0 | F19: =iferror(D19/'Periodo Anterior'!D19-1,"") | H19: =COUNTIFS(Data!$A:$A,">="&'PT Reporte SDR'!$C$3,Data!$A:$A,"<="&'PT Reporte SDR'!$D$3,Data!$AG:$AG,"No") -> 0 | I19: =COUNTIFS(Data!$A:$A,">="&'PT Reporte SDR'!$C$3,Data!$A:$A,"<="&'PT Reporte SDR'!$D$3,Data!$BI:$BI,I5,Data!$AJ:$AJ,"No") -> 0 | J19: =COUNTIFS(Data!$A:$A,">="&'PT Reporte SDR'!$C$3,Data!$A:$A,"<="&'PT Reporte SDR'!$D$3,Data!$BI:$BI,J5,Data!$AJ:$AJ,"No") -> 0
C20: Otras razones | D20: =H20 -> 0 | E20: =IFERROR(D20/$D$12,0) -> 0 | F20: =iferror(D20/'Periodo Anterior'!D20-1,"") | H20: =H99 -> 0 | I20: =I99 -> 0 | J20: =J99 -> 0
C21: Total Leads en seguimiento para venta | D21: =H21 -> 0 | E21: =IFERROR(D21/$D$12,0) -> 0 | F21: =iferror(D21/'Periodo Anterior'!D21-1,"") | H21: =COUNTIFS(Data!$A:$A,">="&'PT Reporte SDR'!$C$3,Data!$A:$A,"<="&'PT Reporte SDR'!$D$3,Data!$W:$W,"En Seguimiento") -> 0 | I21: =COUNTIFS(Data!$A:$A,">="&'PT Reporte SDR'!$C$3,Data!$A:$A,"<="&'PT Reporte SDR'!$D$3,Data!$BI:$BI,I5,Data!$BK:$BK,"SEGUIMIENTO") -> 0 | J21: =COUNTIFS(Data!$A:$A,">="&'PT Reporte SDR'!$C$3,Data!$A:$A,"<="&'PT Reporte SDR'!$D$3,Data!$BI:$BI,J5,Data!$BK:$BK,"SEGUIMIENTO") -> 0
C22: Total Leads Asignados a Ventas | D22: =H22 -> 0 | E22: =iferror(D22/D17,"0%") -> 0 | F22: =iferror(D22/'Periodo Anterior'!D22-1,"") | H22: =COUNTIFS(Data!$A:$A,">="&'PT Reporte SDR'!$C$3,Data!$A:$A,"<="&'PT Reporte SDR'!$D$3,Data!$W:$W,"Paso a ventas") -> 0 | I22: =COUNTIFS(Data!$A:$A,">="&'PT Reporte SDR'!$C$3,Data!$A:$A,"<="&'PT Reporte SDR'!$D$3,Data!$BI:$BI,I5,Data!$BK:$BK,"Pase a ventas") -> 0 | J22: =COUNTIFS(Data!$A:$A,">="&'PT Reporte SDR'!$C$3,Data!$A:$A,"<="&'PT Reporte SDR'!$D$3,Data!$BI:$BI,J5,Data!$BK:$BK,"Pase a ventas") -> 0
C23: Leads Asignados a Ventas Periodo Actual | D23: =H23 -> 6 | E23: =IFERROR(D23/D17,0) -> 2 | F23: =iferror(D23/'Periodo Anterior'!D23-1,"") | H23: 6
C24: Leads Asignados a Ventas Carry-Over | D24: =H24 -> 0 | E24: =IFERROR(D24/#REF!,0) -> 0 | F24: =iferror(D24/'Periodo Anterior'!D24-1,"") | H24: =COUNTIFS(Data!$A:$A,">="&'PT Reporte SDR'!$C$4,Data!$A:$A,"<="&'PT Reporte SDR'!$D$4,Data!$AR:$AR,">="&'PT Reporte SDR'!$C$3,Data!$AR:$AR,"<="&'PT Reporte SDR'!$D$3,Data!$W:$W,"Paso a ventas") -> 0
C25: Leads Contactados por Ventas | D25: =H25 | E25: =D25/D22 -> #DIV/0! | F25: =iferror(D25/'Periodo Anterior'!D25-1,"")
C26: Leads Contactados por Ventas con Respuesta | D26: =H26 | E26: =IFERROR(D26/D22,0) -> 0 | F26: =iferror(D26/'Periodo Anterior'!D26-1,"")
C27: No se envio cotizacion | D27: =H27 | E27: =iferror(D27/$D$116,0) -> 0 | F27: =iferror(D27/'Periodo Anterior'!D27-1,"")
C28: Tasa de Atención | D28: =H28 | F28: =iferror(D28/'Periodo Anterior'!D28-1,"")
C29: Número de Cotizaciones | D29: =H29 | E29: =IFERROR(D29/D26,0) -> 0 | F29: =iferror(D29/'Periodo Anterior'!D29-1,"")
C30: Monto de Cotización | D30: =H30 | F30: =iferror(D30/'Periodo Anterior'!D30-1,"")
C31: Ticket Promedio de Cotizaciones | D31: =H31 | F31: =iferror(D31/'Periodo Anterior'!D31-1,"")
C32: Leads Perdidos | D32: =H32 | E32: =IFERROR(D32/D26,0) -> 0 | F32: =iferror(D32/'Periodo Anterior'!D32-1,"")
C33: Leads en Seguimiento | D33: =H33 | E33: =IFERROR(D33/D26,0) -> 0 | F33: =iferror(D33/'Periodo Anterior'!D33-1,"")
C34: Temperatura de Lead | D34: =H34 | F34: =iferror(D34/'Periodo Anterior'!D34-1,"")
C35: Frio | D35: =H35 | F35: =iferror(D35/'Periodo Anterior'!D35-1,"")
C36: Tibio | D36: =H36 | F36: =iferror(D36/'Periodo Anterior'!D36-1,"")
C37: Caliente | D37: =H37 | F37: =iferror(D37/'Periodo Anterior'!D37-1,"")
C38: Total Número de Serv Confirmados (#) | D38: =H38 | E38: =IFERROR(D38/$D$29,0) -> 0 | F38: =iferror(D38/'Periodo Anterior'!D38-1,"")
C39: Número de Confirmados Periodo Actual (#) | D39: =H39 | E39: =IFERROR(D39/$D$29,0) -> 0 | F39: =iferror(D39/'Periodo Anterior'!D39-1,"")
C40: Número de Confirmados Carry-Over (#) | D40: =H40 | E40: =IFERROR(D40/$D$29,0) -> 0 | F40: =iferror(D40/'Periodo Anterior'!D40-1,"")
C41: Total Monto de Confirmados ($) | D41: =H41 | E41: =IFERROR(D41/$D$30,0) -> 0 | F41: =iferror(D41/'Periodo Anterior'!D41-1,"")
...

Sheet Reporte SDR 
C3: IAAPA | FUNNEL REPORT | SDR | REALTIME
C4: Day In | D4: Day Out
C5: 45778 | D5: 45997
C6: =EOMONTH(C5,-2)+1 -> 45748 | D6: =EDATE(D5, -1) -> 45967
C7: MÉTRICA | D7: TOTAL | E7: % | F7: Δ% vs PP | H7: Total | I7: % | J7: Δ% vs PP | K7: Manufacturers | L7: % | M7: Δ% vs PP | N7: Individuals | O7: % | P7: Δ% vs PP | S7: Agosto
C8: Total Leads SDR | D8: =H8 -> 0 | F8: =iferror(D8/'PT Reporte SDR'!D6-1,"") | H8: =COUNTIFS(Data!$A:$A,">="&'Reporte SDR '!$C$5,Data!$A:$A,"<="&'Reporte SDR '!$D$5) -> 0 | J8: =iferror(H8/'PT Reporte SDR'!H6-1,"") | K8: =COUNTIFS(Data!$A:$A,">="&'Reporte SDR '!$C$5,Data!$A:$A,"<="&'Reporte SDR '!$D$5,Data!$BI:$BI,K7) -> 0 | M8: =iferror(K8/'PT Reporte SDR'!K6-1,"") | N8: =COUNTIFS(Data!$A:$A,">="&'Reporte SDR '!$C$5,Data!$A:$A,"<="&'Reporte SDR '!$D$5,Data!$BI:$BI,N7) -> 0 | P8: =iferror(N8/'PT Reporte SDR'!N6-1,"") | S8: Pagados | T8: 4 | W8: Cerrados carry over
C9: Prueba | D9: =Sum(H9+K9+N9) -> 0 | E9: =iferror(D9/$D$8,"0%") -> 0% | F9: =iferror(D9/'PT Reporte SDR'!D65-1,"") | H9: =COUNTIFS(Data!$A:$A,">="&'Reporte SDR '!$C$5,Data!$A:$A,"<="&'Reporte SDR '!$D$5,Data!$X:$X,C9) -> 0 | I9: =iferror(H9/$D$50,0) -> 0 | J9: =iferror(H9/'PT Reporte SDR'!H65-1,"") | K9: =COUNTIFS(Data!$A:$A,">="&'Reporte SDR '!$C$5,Data!$A:$A,"<="&'Reporte SDR '!$D$5,Data!$BI:$BI,$H$7,Data!$CM:$CM,C9) -> 0 | L9: =iferror(K9/$D$50,0) -> 0 | M9: =iferror(K9/'PT Reporte SDR'!K65-1,"") | N9: =COUNTIFS(Data!$A:$A,">="&'Reporte SDR '!$C$5,Data!$A:$A,"<="&'Reporte SDR '!$D$5,Data!$BI:$BI,$H$7,Data!$CM:$CM,C9) -> 0 | O9: =iferror(N9/$D$50,0) -> 0 | P9: =iferror(N9/'PT Reporte SDR'!N65-1,"")
C10: Total Leads Incontactables por base de datos | D10: =H10 -> 0 | E10: =iferror(D10/$D$8,"0%") -> 0% | F10: =iferror(D10/'PT Reporte SDR'!D7-1,"") | H10: =H50 -> 0 | I10: =iferror(H10/$D$8,"0%") -> 0% | J10: =iferror(H10/'PT Reporte SDR'!H7-1,"") | K10: =K50 -> 0 | L10: =iferror(K10/$D$8,"0%") -> 0% | M10: =iferror(K10/'PT Reporte SDR'!K7-1,"") | N10: =N50 -> 0 | O10: =iferror(N10/$D$8,"0%") -> 0% | P10: =iferror(N10/'PT Reporte SDR'!N7-1,"")
C11: Total Leads Contactables | D11: =H11 -> 0 | E11: =iferror(D11/$D$8,"0%") -> 0% | F11: =iferror(D11/'PT Reporte SDR'!D8-1,"") | H11: =H8-H10-H9 -> 0 | I11: =iferror(H11/$D$8,"0%") -> 0% | J11: =iferror(H11/'PT Reporte SDR'!H8-1,"") | K11: =K8-K10 -> 0 | L11: =iferror(K11/$D$8,"0%") -> 0% | M11: =iferror(K11/'PT Reporte SDR'!K8-1,"") | N11: =N8-N10 -> 0 | O11: =iferror(N11/$D$8,"0%") -> 0% | P11: =iferror(N11/'PT Reporte SDR'!N8-1,"")
C12: Total Leads Contactados (con al menos 1 Toque) | D12: =H12 -> 3 | E12: =iferror(D12/D11,"0%") -> 0% | F12: =iferror(D12/'PT Reporte SDR'!D9-1,"") | H12: =COUNTIFS(Data!$A:$A,">="&'Reporte SDR '!$C$5,Data!$A:$A,"<="&'Reporte SDR '!$D$5,Data!$Y:$Y,"<>")+3 -> 3 | I12: =iferror(H12/H11,"0%") -> 0% | J12: =iferror(H12/'PT Reporte SDR'!H9-1,"") | K12: =COUNTIFS(Data!$A:$A,">="&'Reporte SDR '!$C$5,Data!$A:$A,"<="&'Reporte SDR '!$D$5,Data!$BI:$BI,K7,Data!$AT:$AT,"<>")-K10 -> 0 | L12: =iferror(K12/K11,"0%") -> 0% | M12: =iferror(K12/'PT Reporte SDR'!K9-1,"") | N12: =COUNTIFS(Data!$A:$A,">="&'Reporte SDR '!$C$5,Data!$A:$A,"<="&'Reporte SDR '!$D$5,Data!$BI:$BI,N7,Data!$AT:$AT,"<>")-N10 -> 0 | O12: =iferror(N12/N11,"0%") -> 0% | P12: =iferror(N12/'PT Reporte SDR'!N9-1,"")
C13: Total Lead en Proceso de Contacto (aún sin respuesta) | D13: =H13 -> -15 | E13: =iferror(D13/$D$8,"0%") -> 0% | F13: =iferror(D13/'PT Reporte SDR'!D10-1,"") -> -1.2112676 | H13: =COUNTIFS(Data!$A:$A,">="&'Reporte SDR '!$C$5,Data!$A:$A,"<="&'Reporte SDR '!$D$5,Data!$W:$W,"Contactado sin Respuesta")-15 -> -15 | I13: =iferror(H13/$D$8,"0%") -> 0% | J13: =iferror(H13/'PT Reporte SDR'!H10-1,"") -> -1.2112676 | K13: =COUNTIFS(Data!$A:$A,">="&'Reporte SDR '!$C$5,Data!$A:$A,"<="&'Reporte SDR '!$D$5,Data!$BI:$BI,K7,Data!$BK:$BK,"No respondio") -> 0 | L13: =iferror(K13/$D$8,"0%") -> 0% | M13: =iferror(K13/'PT Reporte SDR'!K10-1,"") | N13: =COUNTIFS(Data!$A:$A,">="&'Reporte SDR '!$C$5,Data!$A:$A,"<="&'Reporte SDR '!$D$5,Data!$BI:$BI,N7,Data!$BK:$BK,"No respondio") -> 0 | O13: =iferror(N13/$D$8,"0%") -> 0% | P13: =iferror(N13/'PT Reporte SDR'!N10-1,"")
C14: Total Leads Contactados sin Respuesta (6to Toque o más) | D14: =H14 -> -4 | E14: =iferror(IFERROR(D14/D12,0),"") -> -1.3333333 | F14: =iferror(D14/'PT Reporte SDR'!D11-1,"") | H14: =COUNTIFS(Data!$A:$A,">="&'Reporte SDR '!$C$5,Data!$A:$A,"<="&'Reporte SDR '!$D$5,Data!$AA:$AA,"<5")-4 -> -4 | I14: =iferror(IFERROR(H14/H12,0),"") -> -1.3333333 | J14: =iferror(H14/'PT Reporte SDR'!H11-1,"") | K14: =COUNTIFS(Data!$A:$A,">="&'Reporte SDR '!$C$5,Data!$A:$A,"<="&'Reporte SDR '!$D$5,Data!$BI:$BI,K7,Data!$AT:$AT,">=6") -> 0 | L14: =iferror(IFERROR(K14/K12,0),"") -> 0 | M14: =iferror(K14/'PT Reporte SDR'!K11-1,"") | N14: =COUNTIFS(Data!$A:$A,">="&'Reporte SDR '!$C$5,Data!$A:$A,"<="&'Reporte SDR '!$D$5,Data!$BI:$BI,N7,Data!$AT:$AT,">=6") -> 0 | O14: =iferror(IFERROR(N14/N12,0),"") -> 0 | P14: =iferror(N14/'PT Reporte SDR'!N11-1,"")
C15: Total Leads Contactados con Respuesta | D15: =H15 -> 13 | E15: =iferror(D15/D11,"0%") -> 0% | F15: =iferror(D15/'PT Reporte SDR'!D12-1,"") | H15: =H56-15 -> 13 | I15: =iferror(H15/H11,"0%") -> 0% | J15: =iferror(H15/'PT Reporte SDR'!H12-1,"") | K15: =COUNTIFS(Data!$A:$A,">="&'Reporte SDR '!$C$5,Data!$A:$A,"<="&'Reporte SDR '!$D$5,Data!$BI:$BI,K7,Data!$BK:$BK,"Pase a ventas")+COUNTIFS(Data!$A:$A,">="&'Reporte SDR '!$C$5,Data!$A:$A,"<="&'Reporte SDR '!$D$5,Data!$BI:$BI,K7,Data!$BK:$BK,"Descartado")+COUNTIFS(Data!$A:$A,">="&'Reporte SDR '!$C$5,Data!$A:$A,"<="&'Reporte SDR '!$D$5,Data!$BI:$BI,K7,Data!$BK:$BK,"Pidio llamar mas tarde")+COUNTIFS(Data!$A:$A,">="&'Reporte SDR '!$C$5,Data!$A:$A,"<="&'Reporte SDR '!$D$5,Data!$BI:$BI,K7,Data!$BK:$BK,"Contesta y Cuelga")+COUNTIFS(Data!$A:$A,">="&'Reporte SDR '!$C$5,Data!$A:$A,"<="&'Reporte SDR '!$D$5,Data!$BI:$BI,K7,Data!$BK:$BK,"Llamar mañana")+COUNTIFS(Data!$A:$A,">="&'Reporte SDR '!$C$5,Data!$A:$A,"<="&'Reporte SDR '!$D$5,Data!$BI:$BI,K7,Data!$BK:$BK,"SEGUIMIENTO") -> 0 | L15: =iferror(K15/K11,"0%") -> 0% | M15: =iferror(K15/'PT Reporte SDR'!K12-1,"") | N15: =COUNTIFS(Data!$A:$A,">="&'Reporte SDR '!$C$5,Data!$A:$A,"<="&'Reporte SDR '!$D$5,Data!$BI:$BI,N7,Data!$BK:$BK,"Pase a ventas")+COUNTIFS(Data!$A:$A,">="&'Reporte SDR '!$C$5,Data!$A:$A,"<="&'Reporte SDR '!$D$5,Data!$BI:$BI,N7,Data!$BK:$BK,"Descartado")+COUNTIFS(Data!$A:$A,">="&'Reporte SDR '!$C$5,Data!$A:$A,"<="&'Reporte SDR '!$D$5,Data!$BI:$BI,N7,Data!$BK:$BK,"Pidio llamar mas tarde")+COUNTIFS(Data!$A:$A,">="&'Reporte SDR '!$C$5,Data!$A:$A,"<="&'Reporte SDR '!$D$5,Data!$BI:$BI,N7,Data!$BK:$BK,"Contesta y Cuelga")+COUNTIFS(Data!$A:$A,">="&'Reporte SDR '!$C$5,Data!$A:$A,"<="&'Reporte SDR '!$D$5,Data!$BI:$BI,N7,Data!$BK:$BK,"Llamar mañana")+COUNTIFS(Data!$A:$A,">="&'Reporte SDR '!$C$5,Data!$A:$A,"<="&'Reporte SDR '!$D$5,Data!$BI:$BI,N7,Data!$BK:$BK,"SEGUIMIENTO") -> 0 | O15: =iferror(N15/N11,"0%") -> 0% | P15: =iferror(N15/'PT Reporte SDR'!N12-1,"")
C16: Total Leads Con Dialogo Completo | D16: =H16 -> 5 | E16: =IFERROR(D16/$D$15,0) -> 0.38461538 | F16: =iferror(D16/'PT Reporte SDR'!D13-1,"") | H16: =COUNTIFS(Data!$A:$A,">="&'Reporte SDR '!$C$5,Data!$A:$A,"<="&'Reporte SDR '!$D$5,Data!$AB:$AB,"Diálogo Completo")+5 -> 5 | I16: =IFERROR(H16/$D$15,0) -> 0.38461538 | J16: =iferror(H16/'PT Reporte SDR'!H13-1,"") | K16: =COUNTIFS(Data!$A:$A,">="&'Reporte SDR '!$C$5,Data!$A:$A,"<="&'Reporte SDR '!$D$5,Data!$BI:$BI,K7,Data!$W:$W,"Diálogo Completo") -> 0 | L16: =IFERROR(K16/$D$15,0) -> 0 | M16: =iferror(K16/'PT Reporte SDR'!K13-1,"") | N16: =COUNTIFS(Data!$A:$A,">="&'Reporte SDR '!$C$5,Data!$A:$A,"<="&'Reporte SDR '!$D$5,Data!$BI:$BI,N7,Data!$W:$W,"Diálogo Completo") -> 0 | O16: =IFERROR(N16/$D$15,0) -> 0 | P16: =iferror(N16/'PT Reporte SDR'!N13-1,"")
C17: Total Leads Intermitentes | D17: =H17 -> 37 | E17: =IFERROR(D17/$D$15,0) -> 2.8461538 | F17: =iferror(D17/'PT Reporte SDR'!D14-1,"") -> 36 | H17: =COUNTIFS(Data!$A:$A,">="&'Reporte SDR '!$C$5,Data!$A:$A,"<="&'Reporte SDR '!$D$5,Data!$AB:$AB,"Intermitente")+37 -> 37 | I17: =IFERROR(H17/$D$15,0) -> 2.8461538 | J17: =iferror(H17/'PT Reporte SDR'!H14-1,"") -> 36 | K17: =COUNTIFS(Data!$A:$A,">="&'Reporte SDR '!$C$5,Data!$A:$A,"<="&'Reporte SDR '!$D$5,Data!$BI:$BI,K7,Data!$W:$W,"Intermitente") -> 0 | L17: =IFERROR(K17/$D$15,0) -> 0 | M17: =iferror(K17/'PT Reporte SDR'!K14-1,"") | N17: =COUNTIFS(Data!$A:$A,">="&'Reporte SDR '!$C$5,Data!$A:$A,"<="&'Reporte SDR '!$D$5,Data!$BI:$BI,N7,Data!$W:$W,"Intermitente") -> 0 | O17: =IFERROR(N17/$D$15,0) -> 0 | P17: =iferror(N17/'PT Reporte SDR'!N14-1,"")
C18: Leads que entendieron comunicación | D18: =H18 -> 0 | E18: =IFERROR(D18/$D$15,0) -> 0 | F18: =iferror(D18/'PT Reporte SDR'!D15-1,"") | H18: =COUNTIFS(Data!$A:$A,">="&'Reporte SDR '!$C$5,Data!$A:$A,"<="&'Reporte SDR '!$D$5,Data!$AF:$AF,"Si") -> 0 | I18: =IFERROR(H18/$D$15,0) -> 0 | J18: =iferror(H18/'PT Reporte SDR'!H15-1,"") | K18: =COUNTIFS(Data!$A:$A,">="&'Reporte SDR '!$C$5,Data!$A:$A,"<="&'Reporte SDR '!$D$5,Data!$BI:$BI,K7,Data!$AJ:$AJ,"Si") -> 0 | L18: =IFERROR(K18/$D$15,0) -> 0 | M18: =iferror(K18/'PT Reporte SDR'!K15-1,"") | N18: =COUNTIFS(Data!$A:$A,">="&'Reporte SDR '!$C$5,Data!$A:$A,"<="&'Reporte SDR '!$D$5,Data!$BI:$BI,N7,Data!$AJ:$AJ,"Si") -> 0 | O18: =IFERROR(N18/$D$15,0) -> 0 | P18: =iferror(N18/'PT Reporte SDR'!N15-1,"")
C19: Leads que no entendieron comunicación | D19: =H19 -> 9 | E19: =IFERROR(D19/$D$15,0) -> 0.69230769 | F19: =iferror(D19/'PT Reporte SDR'!D16-1,"") | H19: =COUNTIFS(Data!$A:$A,">="&'Reporte SDR '!$C$5,Data!$A:$A,"<="&'Reporte SDR '!$D$5,Data!$AF:$AF,"No")+9 -> 9 | I19: =IFERROR(H19/$D$15,0) -> 0.69230769 | J19: =iferror(H19/'PT Reporte SDR'!H16-1,"") | K19: =COUNTIFS(Data!$A:$A,">="&'Reporte SDR '!$C$5,Data!$A:$A,"<="&'Reporte SDR '!$D$5,Data!$BI:$BI,K7,Data!$AJ:$AJ,"No") -> 0 | L19: =IFERROR(K19/$D$15,0) -> 0 | M19: =iferror(K19/'PT Reporte SDR'!K16-1,"") | N19: =COUNTIFS(Data!$A:$A,">="&'Reporte SDR '!$C$5,Data!$A:$A,"<="&'Reporte SDR '!$D$5,Data!$BI:$BI,N7,Data!$AJ:$AJ,"No") -> 0 | O19: =IFERROR(N19/$D$15,0) -> 0 | P19: =iferror(N19/'PT Reporte SDR'!N16-1,"")
C20: Leads que mostraron interés | D20: =H20 -> 39 | E20: =IFERROR(D20/$D$15,0) -> 3 | F20: =iferror(D20/'PT Reporte SDR'!D17-1,"") -> 12 | H20: =COUNTIFS(Data!$A:$A,">="&'Reporte SDR '!$C$5,Data!$A:$A,"<="&'Reporte SDR '!$D$5,Data!$AG:$AG,"Si")+39 -> 39 | I20: =IFERROR(H20/$D$15,0) -> 3 | J20: =iferror(H20/'PT Reporte SDR'!H17-1,"") -> 12 | K20: =COUNTIFS(Data!$A:$A,">="&'Reporte SDR '!$C$5,Data!$A:$A,"<="&'Reporte SDR '!$D$5,Data!$BI:$BI,K7,Data!$BK:$BK,"Pase a ventas") -> 0 | L20: =IFERROR(K20/$D$15,0) -> 0 | M20: =iferror(K20/'PT Reporte SDR'!K17-1,"") | N20: =COUNTIFS(Data!$A:$A,">="&'Reporte SDR '!$C$5,Data!$A:$A,"<="&'Reporte SDR '!$D$5,Data!$BI:$BI,N7,Data!$BK:$BK,"Pase a ventas") -> 0 | O20: =IFERROR(N20/$D$15,0) -> 0 | P20: =iferror(N20/'PT Reporte SDR'!N17-1,"")
C21: Total Leads Descartados | D21: =H21 -> 5 | E21: =iferror(D21/D8,"0%") -> 0% | F21: =iferror(D21/'PT Reporte SDR'!D18-1,"") | H21: =H22+H23 -> 5 | I21: =iferror(H21/H8,"0%") -> 0% | J21: =iferror(H21/'PT Reporte SDR'!H18-1,"") | K21: =K22+K23 -> 0 | L21: =iferror(K21/K8,"0%") -> 0% | M21: =iferror(K21/'PT Reporte SDR'!K18-1,"") | N21: =N22+N23 -> 0 | O21: =iferror(N21/N8,"0%") -> 0% | P21: =iferror(N21/'PT Reporte SDR'!N18-1,"")
C22: Leads que no mostraron interés | D22: =H22 -> 2 | E22: =IFERROR(D22/$D$15,0) -> 0.15384615 | F22: =iferror(D22/'PT Reporte SDR'!D19-1,"") | H22: =COUNTIFS(Data!$A:$A,">="&'Reporte SDR '!$C$5,Data!$A:$A,"<="&'Reporte SDR '!$D$5,Data!$AG:$AG,"No")+2 -> 2 | I22: =IFERROR(H22/$D$15,0) -> 0.15384615 | J22: =iferror(H22/'PT Reporte SDR'!H19-1,"") | K22: =COUNTIFS(Data!$A:$A,">="&'Reporte SDR '!$C$5,Data!$A:$A,"<="&'Reporte SDR '!$D$5,Data!$BI:$BI,K7,Data!$AJ:$AJ,"No") -> 0 | L22: =IFERROR(K22/$D$15,0) -> 0 | M22: =iferror(K22/'PT Reporte SDR'!K19-1,"") | N22: =COUNTIFS(Data!$A:$A,">="&'Reporte SDR '!$C$5,Data!$A:$A,"<="&'Reporte SDR '!$D$5,Data!$BI:$BI,N7,Data!$AJ:$AJ,"No") -> 0 | O22: =IFERROR(N22/$D$15,0) -> 0 | P22: =iferror(N22/'PT Reporte SDR'!N19-1,"")
C23: Otras razones | D23: =H23 -> 3 | E23: =IFERROR(D23/$D$15,0) -> 0.23076923 | F23: =iferror(D23/'PT Reporte SDR'!D20-1,"") | H23: =H83 -> 3 | I23: =IFERROR(H23/$D$15,0) -> 0.23076923 | J23: =iferror(H23/'PT Reporte SDR'!H20-1,"") | K23: =K83 -> 0 | L23: =IFERROR(K23/$D$15,0) -> 0 | M23: =iferror(K23/'PT Reporte SDR'!K20-1,"") | N23: =N83 -> 0 | O23: =IFERROR(N23/$D$15,0) -> 0 | P23: =iferror(N23/'PT Reporte SDR'!N20-1,"")
C24: Total Leads en seguimiento para venta | D24: =H24 -> 0 | E24: =IFERROR(D24/$D$15,0) -> 0 | F24: =iferror(D24/'PT Reporte SDR'!D21-1,"") | H24: =COUNTIFS(Data!$A:$A,">="&'Reporte SDR '!$C$5,Data!$A:$A,"<="&'Reporte SDR '!$D$5,Data!$W:$W,"En Seguimiento") -> 0 | I24: =IFERROR(H24/$D$15,0) -> 0 | J24: =iferror(H24/'PT Reporte SDR'!H21-1,"") | K24: =COUNTIFS(Data!$A:$A,">="&'Reporte SDR '!$C$5,Data!$A:$A,"<="&'Reporte SDR '!$D$5,Data!$BI:$BI,K7,Data!$BK:$BK,"SEGUIMIENTO") -> 0 | L24: =IFERROR(K24/$D$15,0) -> 0 | M24: =iferror(K24/'PT Reporte SDR'!K21-1,"") | N24: =COUNTIFS(Data!$A:$A,">="&'Reporte SDR '!$C$5,Data!$A:$A,"<="&'Reporte SDR '!$D$5,Data!$BI:$BI,N7,Data!$BK:$BK,"SEGUIMIENTO") -> 0 | O24: =IFERROR(N24/$D$15,0) -> 0 | P24: =iferror(N24/'PT Reporte SDR'!N21-1,"")
C25: Monto aproximado de Inversión en seguimiento a venta | D25: =H25 -> #N/A | H25: =SUMIFS(Data!$AP:$AP,Data!$A:$A,">="&'Reporte SDR '!$C$5,Data!$A:$A,"<="&'Reporte SDR '!$D$5,Data!$W:$W,"En Seguimiento")+1700 -> #N/A
C26: Total Leads Asignados a Ventas | D26: =H26 -> 0 | E26: =iferror(D26/D20,"0%") -> 0 | F26: =iferror(D26/'PT Reporte SDR'!D22-1,"") | H26: =COUNTIFS(Data!$A:$A,">="&'Reporte SDR '!$C$5,Data!$A:$A,"<="&'Reporte SDR '!$D$5,Data!$W:$W,"Paso a ventas") -> 0 | I26: =iferror(H26/H20,"0%") -> 0 | J26: =iferror(H26/'PT Reporte SDR'!H22-1,"") | K26: =COUNTIFS(Data!$A:$A,">="&'Reporte SDR '!$C$5,Data!$A:$A,"<="&'Reporte SDR '!$D$5,Data!$BI:$BI,K7,Data!$BK:$BK,"Pase a ventas") -> 0 | L26: =iferror(K26/K20,"0%") -> 0% | M26: =iferror(K26/'PT Reporte SDR'!K22-1,"") | N26: =COUNTIFS(Data!$A:$A,">="&'Reporte SDR '!$C$5,Data!$A:$A,"<="&'Reporte SDR '!$D$5,Data!$BI:$BI,N7,Data!$BK:$BK,"Pase a ventas") -> 0 | O26: =iferror(N26/N20,"0%") -> 0% | P26: =iferror(N26/'PT Reporte SDR'!N22-1,"")
C27: Monto de inversión asignada a ventas | D27: =H27 -> #N/A | E27: $ | F27: =iferror(D27/'PT Reporte SDR Brazil'!D28-1,"") | H27: =SUMIFS(Data!$AP:$AP,Data!$A:$A,">="&'Report LATAM'!$C$5,Data!$A:$A,"<="&'Report LATAM'!$D$5,Data!$W:$W,"Paso a Ventas")+2000 -> #N/A | J27: =iferror(H27/'PT Reporte SDR Brazil'!H28-1,"")
C28: Leads Asignados a Ventas Periodo Actual | D28: =H28 -> 0 | E28: =IFERROR(D28/D20,0) -> 0 | F28: =iferror(D28/'PT Reporte SDR Brazil'!D23-1,"") -> -1 | H28: =COUNTIFS(Data!$A:$A,">="&'Reporte SDR '!$C$5,Data!$A:$A,"<="&'Reporte SDR '!$D$5,Data!$W:$W,"Paso a ventas") -> 0 | I28: =IFERROR(H28/H20,0) -> 0 | J28: =iferror(H28/'PT Reporte SDR Brazil'!H23-1,"") -> -1
C29: Monto de Inversión asignada a Ventas Periodo Actual | D29: =H29 -> #N/A | E29: =IFERROR(D29/D26,0) -> 0 | F29: =iferror(D29/'PT Reporte SDR Brazil'!D26-1,"") | H29: =SUMIFS(Data!$AP:$AP,Data!$A:$A,">="&'Report LATAM'!$C$5,Data!$A:$A,"<="&'Report LATAM'!$D$5,Data!$W:$W,"Paso a Ventas")+2000 -> #N/A | I29: =IFERROR(H29/H26,0) -> 0 | J29: =iferror(H29/'PT Reporte SDR Brazil'!H26-1,"")
C30: Leads Asignados a Ventas Carry-Over | D30: =H30 -> 3 | E30: =IFERROR(D30/#REF!,0) -> 0 | F30: =iferror(D30/'PT Reporte SDR Brazil'!D24-1,"") | H30: =COUNTIFS(Data!$AR:$AR,">="&'Reporte SDR '!$C$5,Data!$AR:$AR,"<="&'Reporte SDR '!$D$5,Data!$A:$A,">="&'Reporte SDR '!$C$6,Data!$A:$A,"<="&'Reporte SDR '!$D$6,Data!$W:$W,"Paso a ventas")+3 -> 3 | I30: =IFERROR(H30/#REF!,0) -> 0 | J30: =iferror(H30/'PT Reporte SDR Brazil'!H24-1,"")
C31: Monto de Inversión asignada a Ventas Carry-Over (Leads Mes anterior) | D31: =H31 -> #N/A | E31: =iferror(D31/$D$78,0) -> 0 | F31: =iferror(D31/'PT Reporte SDR Brazil'!D27-1,"") | H31: =SUMIFS(Data!$BQ:$BQ,Data!$AR:$AR,">="&'Reporte SDR '!$C$5,Data!$AR:$AR,"<="&'Reporte SDR '!$D$5,Data!$A:$A,">="&'Reporte SDR '!$C$6,Data!$A:$A,"<="&'Reporte SDR '!$D$6,Data!$W:$W,"Paso a ventas")+1130 -> #N/A | I31: =iferror(H31/$D$78,0) -> 0 | J31: =iferror(H31/'PT Reporte SDR Brazil'!H27-1,"")
C32: Deals con Link de Pago activo | D32: =H32 -> -2 | H32: =COUNTIFS(Data!$A:$A,">="&'Reporte SDR '!$C$5,Data!$A:$A,"<="&'Reporte SDR '!$D$5,Data!$BZ:$BZ,"Si",Data!$BL:$BL,"<>Vendido")-2 -> -2
C33: Monto de Inversión con Link de Pago | D33: =H33 -> #N/A | H33: =SUMIFS(Data!$BQ:$BQ,Data!$A:$A,">="&'Reporte SDR '!$C$5,Data!$A:$A,"<="&'Reporte SDR '!$D$5,Data!$BZ:$BZ,"Si",Data!$BL:$BL,"<>Vendido")+SUMIFS(Data!$BP:$BP,Data!$A:$A,">="&'Reporte SDR '!$C$5,Data!$A:$A,"<="&'Reporte SDR '!$D$5,Data!$BZ:$BZ,"Si",Data!$BL:$BL,"<>Vendido")+1365 -> #N/A
C34: Cierres de Deals Nuevos Pagados | D34: =H34 -> -10 | F34: =iferror(D34/'PT Reporte SDR Brazil'!D35-1,"") | H34: =COUNTIFS(Data!$A:$A,">="&'Reporte SDR '!$C$5,Data!$A:$A,"<="&'Reporte SDR '!$D$5,Data!$BL:$BL,"Vendido",Data!$BY:$BY,">="&'Reporte SDR '!$C$5,Data!$BY:$BY,"<="&'Reporte SDR '!$D$5)-10 -> -10 | J34: =iferror(H34/'PT Reporte SDR Brazil'!H35-1,"")
C35: Monto de nuevos cierres | D35: =H35 -> #N/A | F35: =iferror(D35/'PT Reporte SDR Brazil'!D36-1,"") | H35: =SUMIFS(Data!$BQ:$BQ,Data!$A:$A,">="&'Reporte SDR '!$C$5,Data!$A:$A,"<="&'Reporte SDR '!$D$5,Data!$BL:$BL,"Vendido",Data!$BY:$BY,">="&'Reporte SDR '!$C$5,Data!$BY:$BY,"<="&'Reporte SDR '!$D$5)+SUMIFS(Data!$BR:$BR,Data!$A:$A,">="&'Reporte SDR '!$C$5,Data!$A:$A,"<="&'Reporte SDR '!$D$5,Data!$BL:$BL,"Vendido",Data!$BY:$BY,">="&'Reporte SDR '!$C$5,Data!$BY:$BY,"<="&'Reporte SDR '!$D$5)-4005 -> #N/A | J35: =iferror(H35/'PT Reporte SDR Brazil'!H36-1,"")
C36: Cierres de Deals Pagados por Rejoin (aquellos que fueron miembros y se vuelven a unir a IAAPA) | D36: =H36 -> 0 | H36: =COUNTIFS(Data!$A:$A,">="&'Reporte SDR '!$C$5,Data!$A:$A,"<="&'Reporte SDR '!$D$5,Data!$BL:$BL,"Vendido",Data!$CA:$CA,"Si") -> 0
C37: Monto de cierres por renovación | D37: =H37 -> #N/A | H37: =SUMIFS(Data!$BQ:$BQ,Data!$A:$A,">="&'Reporte SDR '!$C$5,Data!$A:$A,"<="&'Reporte SDR '!$D$5,Data!$BL:$BL,"Vendido",Data!$CA:$CA,"Si") -> #N/A
C38: Cierres de Deals Pagados Total | D38: =H38 -> 4 | H38: =COUNTIFS(Data!$A:$A,">="&'Reporte SDR '!$C$5,Data!$A:$A,"<="&'Reporte SDR '!$D$5,Data!$BL:$BL,"Vendido")+4 -> 4
C39: Monto de cierres Total | D39: =H39 -> #N/A | H39: =SUMIFS(Data!$BQ:$BQ,Data!$A:$A,">="&'Reporte SDR '!$C$5,Data!$A:$A,"<="&'Reporte SDR '!$D$5,Data!$BL:$BL,"Vendido")+SUMIFS(Data!$BR:$BR,Data!$A:$A,">="&'Reporte SDR '!$C$5,Data!$A:$A,"<="&'Reporte SDR '!$D$5,Data!$BL:$BL,"Vendido")+4645 -> #N/A
C40: Monto asignado a Ventas Total todos los tiempos | D40: =H40 -> #N/A | E40: =IFERROR(D40/D29,0) -> 0 | F40: =iferror(D40/'PT Reporte SDR Brazil'!D29-1,"") | H40: =SUMIFS(Data!$BQ:$BQ,Data!$A:$A,">="&'Reporte SDR '!$H$4,Data!$A:$A,"<="&'Reporte SDR '!$I$4,Data!$W:$W,"Paso a ventas")+SUMIFS(Data!$BR:$BR,Data!$A:$A,">="&'Reporte SDR '!$H$4,Data!$A:$A,"<="&'Reporte SDR '!$I$4,Data!$W:$W,"Paso a ventas")+14325 -> #N/A | I40: =IFERROR(H40/H29,0) -> 0 | J40: =iferror(H40/'PT Reporte SDR Brazil'!H29-1,"")
C41: Monto asignado a Ventas Historico aún en seguimiento | D41: =H41 -> #N/A | F41: =iferror(D41/'PT Reporte SDR Brazil'!D30-1,"") | H41: =SUMIFS(Data!$BQ:$BQ,Data!$A:$A,">="&'Reporte SDR '!$H$5,Data!$A:$A,"<="&'Reporte SDR '!$I$5,Data!$W:$W,"Paso a ventas")+SUMIFS(Data!$BR:$BR,Data!$A:$A,">="&'Reporte SDR '!$H$5,Data!$A:$A,"<="&'Reporte SDR '!$I$5,Data!$W:$W,"Paso a ventas")+13885 -> #N/A | J41: =iferror(H41/'PT Reporte SDR Brazil'!H30-1,"")
C42: Monto asignado a ventas Perdido | D42: =H42 -> #N/A | E42: =IFERROR(D42/D29,0) -> 0 | F42: =iferror(D42/'PT Reporte SDR Brazil'!D32-1,"") | H42: =SUMIFS(Data!$BQ:$BQ,Data!$A:$A,">="&'Reporte SDR '!$H$5,Data!$A:$A,"<="&'Reporte SDR '!$I$5,Data!$W:$W,"Paso a ventas",Data!$BL:$BL,"Perdido")+SUMIFS(Data!$BR:$BR,Data!$A:$A,">="&'Reporte SDR '!$H$5,Data!$A:$A,"<="&'Reporte SDR '!$I$5,Data!$W:$W,"Paso a ventas",Data!$BL:$BL,"Perdido") -> #N/A | I42: =IFERROR(H42/H29,0) -> 0 | J42: =iferror(H42/'PT Reporte SDR Brazil'!H32-1,"")
...

Sheet Copy of Reporte SDR 
C3: IAAPA | FUNNEL REPORT | SDR | REALTIME
C4: Day In | D4: Day Out
C5: 45992 | D5: 46022
C6: =EOMONTH(C5,-2)+1 -> 45962 | D6: =EDATE(D5, -1) -> 45991
C7: MÉTRICA | D7: TOTAL | E7: % | F7: Δ% vs PP | H7: Total | I7: % | J7: Δ% vs PP | K7: Manufacturers | L7: % | M7: Δ% vs PP | N7: Individuals | O7: % | P7: Δ% vs PP | S7: Agosto
C8: Total Leads SDR | D8: =H8 -> 0 | F8: =iferror(D8/'PT Reporte SDR'!D6-1,"") | H8: =COUNTIFS(Data!$A:$A,">="&'Copy of Reporte SDR '!$C$5,Data!$A:$A,"<="&'Copy of Reporte SDR '!$D$5) -> 0 | J8: =iferror(H8/'PT Reporte SDR'!H6-1,"") | K8: =COUNTIFS(Data!$A:$A,">="&'Copy of Reporte SDR '!$C$5,Data!$A:$A,"<="&'Copy of Reporte SDR '!$D$5,Data!$BI:$BI,K7) -> 0 | M8: =iferror(K8/'PT Reporte SDR'!K6-1,"") | N8: =COUNTIFS(Data!$A:$A,">="&'Copy of Reporte SDR '!$C$5,Data!$A:$A,"<="&'Copy of Reporte SDR '!$D$5,Data!$BI:$BI,N7) -> 0 | P8: =iferror(N8/'PT Reporte SDR'!N6-1,"") | S8: Pagados | T8: 4 | W8: Cerrados carry over
C9: Prueba | D9: =Sum(H9+K9+N9) -> 0 | E9: =iferror(D9/$D$8,"0%") -> 0% | F9: =iferror(D9/'PT Reporte SDR'!D65-1,"") | H9: =COUNTIFS(Data!$A:$A,">="&'Copy of Reporte SDR '!$C$5,Data!$A:$A,"<="&'Copy of Reporte SDR '!$D$5,Data!$X:$X,C9) -> 0 | I9: =iferror(H9/$D$49,0) -> 0 | J9: =iferror(H9/'PT Reporte SDR'!H65-1,"") | K9: =COUNTIFS(Data!$A:$A,">="&'Copy of Reporte SDR '!$C$5,Data!$A:$A,"<="&'Copy of Reporte SDR '!$D$5,Data!$BI:$BI,$H$7,Data!$CM:$CM,C9) -> 0 | L9: =iferror(K9/$D$49,0) -> 0 | M9: =iferror(K9/'PT Reporte SDR'!K65-1,"") | N9: =COUNTIFS(Data!$A:$A,">="&'Copy of Reporte SDR '!$C$5,Data!$A:$A,"<="&'Copy of Reporte SDR '!$D$5,Data!$BI:$BI,$H$7,Data!$CM:$CM,C9) -> 0 | O9: =iferror(N9/$D$49,0) -> 0 | P9: =iferror(N9/'PT Reporte SDR'!N65-1,"")
C10: Total Leads Incontactables por base de datos | D10: =H10 -> 0 | E10: =iferror(D10/$D$8,"0%") -> 0% | F10: =iferror(D10/'PT Reporte SDR'!D7-1,"") | H10: =H49 -> 0 | I10: =iferror(H10/$D$8,"0%") -> 0% | J10: =iferror(H10/'PT Reporte SDR'!H7-1,"") | K10: =K49 -> 0 | L10: =iferror(K10/$D$8,"0%") -> 0% | M10: =iferror(K10/'PT Reporte SDR'!K7-1,"") | N10: =N49 -> 0 | O10: =iferror(N10/$D$8,"0%") -> 0% | P10: =iferror(N10/'PT Reporte SDR'!N7-1,"")
C11: Total Leads Contactables | D11: =H11 -> 0 | E11: =iferror(D11/$D$8,"0%") -> 0% | F11: =iferror(D11/'PT Reporte SDR'!D8-1,"") | H11: =H8-H10-H9 -> 0 | I11: =iferror(H11/$D$8,"0%") -> 0% | J11: =iferror(H11/'PT Reporte SDR'!H8-1,"") | K11: =K8-K10 -> 0 | L11: =iferror(K11/$D$8,"0%") -> 0% | M11: =iferror(K11/'PT Reporte SDR'!K8-1,"") | N11: =N8-N10 -> 0 | O11: =iferror(N11/$D$8,"0%") -> 0% | P11: =iferror(N11/'PT Reporte SDR'!N8-1,"")
C12: Total Leads Contactados (con al menos 1 Toque) | D12: =H12 -> 0 | E12: =iferror(D12/D11,"0%") -> 0% | F12: =iferror(D12/'PT Reporte SDR'!D9-1,"") | H12: =COUNTIFS(Data!$A:$A,">="&'Copy of Reporte SDR '!$C$5,Data!$A:$A,"<="&'Copy of Reporte SDR '!$D$5,Data!$Y:$Y,"<>") -> 0 | I12: =iferror(H12/H11,"0%") -> 0% | J12: =iferror(H12/'PT Reporte SDR'!H9-1,"") | K12: =COUNTIFS(Data!$A:$A,">="&'Copy of Reporte SDR '!$C$5,Data!$A:$A,"<="&'Copy of Reporte SDR '!$D$5,Data!$BI:$BI,K7,Data!$AT:$AT,"<>")-K10 -> 0 | L12: =iferror(K12/K11,"0%") -> 0% | M12: =iferror(K12/'PT Reporte SDR'!K9-1,"") | N12: =COUNTIFS(Data!$A:$A,">="&'Copy of Reporte SDR '!$C$5,Data!$A:$A,"<="&'Copy of Reporte SDR '!$D$5,Data!$BI:$BI,N7,Data!$AT:$AT,"<>")-N10 -> 0 | O12: =iferror(N12/N11,"0%") -> 0% | P12: =iferror(N12/'PT Reporte SDR'!N9-1,"")
C13: Total Lead en Proceso de Contacto (aún sin respuesta) | D13: =H13 -> 0 | E13: =iferror(D13/$D$8,"0%") -> 0% | F13: =iferror(D13/'PT Reporte SDR'!D10-1,"") -> -1 | H13: =COUNTIFS(Data!$A:$A,">="&'Copy of Reporte SDR '!$C$5,Data!$A:$A,"<="&'Copy of Reporte SDR '!$D$5,Data!$W:$W,"Contactado sin Respuesta") -> 0 | I13: =iferror(H13/$D$8,"0%") -> 0% | J13: =iferror(H13/'PT Reporte SDR'!H10-1,"") -> -1 | K13: =COUNTIFS(Data!$A:$A,">="&'Copy of Reporte SDR '!$C$5,Data!$A:$A,"<="&'Copy of Reporte SDR '!$D$5,Data!$BI:$BI,K7,Data!$BK:$BK,"No respondio") -> 0 | L13: =iferror(K13/$D$8,"0%") -> 0% | M13: =iferror(K13/'PT Reporte SDR'!K10-1,"") | N13: =COUNTIFS(Data!$A:$A,">="&'Copy of Reporte SDR '!$C$5,Data!$A:$A,"<="&'Copy of Reporte SDR '!$D$5,Data!$BI:$BI,N7,Data!$BK:$BK,"No respondio") -> 0 | O13: =iferror(N13/$D$8,"0%") -> 0% | P13: =iferror(N13/'PT Reporte SDR'!N10-1,"")
C14: Total Leads Contactados sin Respuesta (6to Toque o más) | D14: =H14 -> 0 | E14: =iferror(IFERROR(D14/D12,0),"") -> 0 | F14: =iferror(D14/'PT Reporte SDR'!D11-1,"") | H14: =COUNTIFS(Data!$A:$A,">="&'Copy of Reporte SDR '!$C$5,Data!$A:$A,"<="&'Copy of Reporte SDR '!$D$5,Data!$AA:$AA,"<5") -> 0 | I14: =iferror(IFERROR(H14/H12,0),"") -> 0 | J14: =iferror(H14/'PT Reporte SDR'!H11-1,"") | K14: =COUNTIFS(Data!$A:$A,">="&'Copy of Reporte SDR '!$C$5,Data!$A:$A,"<="&'Copy of Reporte SDR '!$D$5,Data!$BI:$BI,K7,Data!$AT:$AT,">=6") -> 0 | L14: =iferror(IFERROR(K14/K12,0),"") -> 0 | M14: =iferror(K14/'PT Reporte SDR'!K11-1,"") | N14: =COUNTIFS(Data!$A:$A,">="&'Copy of Reporte SDR '!$C$5,Data!$A:$A,"<="&'Copy of Reporte SDR '!$D$5,Data!$BI:$BI,N7,Data!$AT:$AT,">=6") -> 0 | O14: =iferror(IFERROR(N14/N12,0),"") -> 0 | P14: =iferror(N14/'PT Reporte SDR'!N11-1,"")
C15: Total Leads Contactados con Respuesta | D15: =H15 -> 3 | E15: =iferror(D15/D11,"0%") -> 0% | F15: =iferror(D15/'PT Reporte SDR'!D12-1,"") | H15: =H55 -> 3 | I15: =iferror(H15/H11,"0%") -> 0% | J15: =iferror(H15/'PT Reporte SDR'!H12-1,"") | K15: =COUNTIFS(Data!$A:$A,">="&'Copy of Reporte SDR '!$C$5,Data!$A:$A,"<="&'Copy of Reporte SDR '!$D$5,Data!$BI:$BI,K7,Data!$BK:$BK,"Pase a ventas")+COUNTIFS(Data!$A:$A,">="&'Copy of Reporte SDR '!$C$5,Data!$A:$A,"<="&'Copy of Reporte SDR '!$D$5,Data!$BI:$BI,K7,Data!$BK:$BK,"Descartado")+COUNTIFS(Data!$A:$A,">="&'Copy of Reporte SDR '!$C$5,Data!$A:$A,"<="&'Copy of Reporte SDR '!$D$5,Data!$BI:$BI,K7,Data!$BK:$BK,"Pidio llamar mas tarde")+COUNTIFS(Data!$A:$A,">="&'Copy of Reporte SDR '!$C$5,Data!$A:$A,"<="&'Copy of Reporte SDR '!$D$5,Data!$BI:$BI,K7,Data!$BK:$BK,"Contesta y Cuelga")+COUNTIFS(Data!$A:$A,">="&'Copy of Reporte SDR '!$C$5,Data!$A:$A,"<="&'Copy of Reporte SDR '!$D$5,Data!$BI:$BI,K7,Data!$BK:$BK,"Llamar mañana")+COUNTIFS(Data!$A:$A,">="&'Copy of Reporte SDR '!$C$5,Data!$A:$A,"<="&'Copy of Reporte SDR '!$D$5,Data!$BI:$BI,K7,Data!$BK:$BK,"SEGUIMIENTO") -> 0 | L15: =iferror(K15/K11,"0%") -> 0% | M15: =iferror(K15/'PT Reporte SDR'!K12-1,"") | N15: =COUNTIFS(Data!$A:$A,">="&'Copy of Reporte SDR '!$C$5,Data!$A:$A,"<="&'Copy of Reporte SDR '!$D$5,Data!$BI:$BI,N7,Data!$BK:$BK,"Pase a ventas")+COUNTIFS(Data!$A:$A,">="&'Copy of Reporte SDR '!$C$5,Data!$A:$A,"<="&'Copy of Reporte SDR '!$D$5,Data!$BI:$BI,N7,Data!$BK:$BK,"Descartado")+COUNTIFS(Data!$A:$A,">="&'Copy of Reporte SDR '!$C$5,Data!$A:$A,"<="&'Copy of Reporte SDR '!$D$5,Data!$BI:$BI,N7,Data!$BK:$BK,"Pidio llamar mas tarde")+COUNTIFS(Data!$A:$A,">="&'Copy of Reporte SDR '!$C$5,Data!$A:$A,"<="&'Copy of Reporte SDR '!$D$5,Data!$BI:$BI,N7,Data!$BK:$BK,"Contesta y Cuelga")+COUNTIFS(Data!$A:$A,">="&'Copy of Reporte SDR '!$C$5,Data!$A:$A,"<="&'Copy of Reporte SDR '!$D$5,Data!$BI:$BI,N7,Data!$BK:$BK,"Llamar mañana")+COUNTIFS(Data!$A:$A,">="&'Copy of Reporte SDR '!$C$5,Data!$A:$A,"<="&'Copy of Reporte SDR '!$D$5,Data!$BI:$BI,N7,Data!$BK:$BK,"SEGUIMIENTO") -> 0 | O15: =iferror(N15/N11,"0%") -> 0% | P15: =iferror(N15/'PT Reporte SDR'!N12-1,"")
C16: Total Leads Con Dialogo Completo | D16: =H16 -> -2 | E16: =IFERROR(D16/$D$15,0) -> -0.66666667 | F16: =iferror(D16/'PT Reporte SDR'!D13-1,"") | H16: =COUNTIFS(Data!$A:$A,">="&'Copy of Reporte SDR '!$C$5,Data!$A:$A,"<="&'Copy of Reporte SDR '!$D$5,Data!$AB:$AB,"Diálogo Completo")-2 -> -2 | I16: =IFERROR(H16/$D$15,0) -> -0.66666667 | J16: =iferror(H16/'PT Reporte SDR'!H13-1,"") | K16: =COUNTIFS(Data!$A:$A,">="&'Copy of Reporte SDR '!$C$5,Data!$A:$A,"<="&'Copy of Reporte SDR '!$D$5,Data!$BI:$BI,K7,Data!$W:$W,"Diálogo Completo") -> 0 | L16: =IFERROR(K16/$D$15,0) -> 0 | M16: =iferror(K16/'PT Reporte SDR'!K13-1,"") | N16: =COUNTIFS(Data!$A:$A,">="&'Copy of Reporte SDR '!$C$5,Data!$A:$A,"<="&'Copy of Reporte SDR '!$D$5,Data!$BI:$BI,N7,Data!$W:$W,"Diálogo Completo") -> 0 | O16: =IFERROR(N16/$D$15,0) -> 0 | P16: =iferror(N16/'PT Reporte SDR'!N13-1,"")
